Workbook

Sheet Build a Bear
A3: Tier | B3: Type | C3: Physical Defense | D3: Cognitive Defense | E3: Spiritual Defense | F3: Health | G3: Focus | H3: Investiture | I3: Physical Skills | J3: Cognitive Skills | K3: Spiritual Skills | L3: Invested Skills | M3: To Hit Bonus | N3: DPR (Fast) | O3: DPR (Slow)
A4: 1 | B4: Minion | C4: =CONCATENATE(round(((if($R$5=true, StormlightAverages!B4,0)+if($R$6=true, MistbornAverages!B4,0)+if($R$7=true, WarbreakerAverages!B4,0)+if($R$8=true, ElantrisAverages!B4,0)+if($R$9=true, WorldhopperAverages!B4,0))/(if(countif($R$5:$R$9,true)=0, 1, COUNTIF($R$5:$R$9,true)))),0)," (",min(if($R$5=true, StormlightMinimums!B4,100000000000),if($R$6=true, MistbornMinimums!B4,100000000000),if($R$7=true, WarbreakerMinimums!B4,100000000000),if($R$8=true, ElantrisMinimums!B4,100000000000),if($R$9=true, WorldhopperMinimums!B4,100000000000)), ,"-",max(if($R$5=true,StormlightMaximums!B4,0),if($R$6=true,MistbornMaximums!B4,0),if($R$7=true, WarbreakerMaximums!B4,0),if($R$8=true, ElantrisMaximums!B4,0),if($R$9=true, WorldhopperMaximums!B4,0)),")") -> 13 (11-15) | D4: =CONCATENATE(round(((if($R$5=true, StormlightAverages!C4,0)+if($R$6=true, MistbornAverages!C4,0)+if($R$7=true, WarbreakerAverages!C4,0)+if($R$8=true, ElantrisAverages!C4,0)+if($R$9=true, WorldhopperAverages!C4,0))/(if(countif($R$5:$R$9,true)=0, 1, COUNTIF($R$5:$R$9,true)))),0)," (",min(if($R$5=true, StormlightMinimums!C4,100000000000),if($R$6=true, MistbornMinimums!C4,100000000000),if($R$7=true, WarbreakerMinimums!C4,100000000000),if($R$8=true, ElantrisMinimums!C4,100000000000),if($R$9=true, WorldhopperMinimums!C4,100000000000)), ,"-",max(if($R$5=true,StormlightMaximums!C4,0),if($R$6=true,MistbornMaximums!C4,0),if($R$7=true, WarbreakerMaximums!C4,0),if($R$8=true, ElantrisMaximums!C4,0),if($R$9=true, WorldhopperMaximums!C4,0)),")") -> 12 (10-13) | E4: =CONCATENATE(round(((if($R$5=true, StormlightAverages!D4,0)+if($R$6=true, MistbornAverages!D4,0)+if($R$7=true, WarbreakerAverages!D4,0)+if($R$8=true, ElantrisAverages!D4,0)+if($R$9=true, WorldhopperAverages!D4,0))/(if(countif($R$5:$R$9,true)=0, 1, COUNTIF($R$5:$R$9,true)))),0)," (",min(if($R$5=true, StormlightMinimums!D4,100000000000),if($R$6=true, MistbornMinimums!D4,100000000000),if($R$7=true, WarbreakerMinimums!D4,100000000000),if($R$8=true, ElantrisMinimums!D4,100000000000),if($R$9=true, WorldhopperMinimums!D4,100000000000)), ,"-",max(if($R$5=true,StormlightMaximums!D4,0),if($R$6=true,MistbornMaximums!D4,0),if($R$7=true, WarbreakerMaximums!D4,0),if($R$8=true, ElantrisMaximums!D4,0),if($R$9=true, WorldhopperMaximums!D4,0)),")") -> 12 (10-13) | F4: =CONCATENATE(round(((if($R$5=true, StormlightAverages!E4,0)+if($R$6=true, MistbornAverages!E4,0)+if($R$7=true, WarbreakerAverages!E4,0)+if($R$8=true, ElantrisAverages!E4,0)+if($R$9=true, WorldhopperAverages!E4,0))/(if(countif($R$5:$R$9,true)=0, 1, COUNTIF($R$5:$R$9,true)))),0)," (",min(if($R$5=true, StormlightMinimums!E4,100000000000),if($R$6=true, MistbornMinimums!E4,100000000000),if($R$7=true, WarbreakerMinimums!E4,100000000000),if($R$8=true, ElantrisMinimums!E4,100000000000),if($R$9=true, WorldhopperMinimums!E4,100000000000)), ,"-",max(if($R$5=true,StormlightMaximums!E4,0),if($R$6=true,MistbornMaximums!E4,0),if($R$7=true, WarbreakerMaximums!E4,0),if($R$8=true, ElantrisMaximums!E4,0),if($R$9=true, WorldhopperMaximums!E4,0)),")") -> 11 (9-14) | G4: =CONCATENATE(round(((if($R$5=true, StormlightAverages!F4,0)+if($R$6=true, MistbornAverages!F4,0)+if($R$7=true, WarbreakerAverages!F4,0)+if($R$8=true, ElantrisAverages!F4,0)+if($R$9=true, WorldhopperAverages!F4,0))/(if(countif($R$5:$R$9,true)=0, 1, COUNTIF($R$5:$R$9,true)))),0)," (",min(if($R$5=true, StormlightMinimums!F4,100000000000),if($R$6=true, MistbornMinimums!F4,100000000000),if($R$7=true, WarbreakerMinimums!F4,100000000000),if($R$8=true, ElantrisMinimums!F4,100000000000),if($R$9=true, WorldhopperMinimums!F4,100000000000)), ,"-",max(if($R$5=true,StormlightMaximums!F4,0),if($R$6=true,MistbornMaximums!F4,0),if($R$7=true, WarbreakerMaximums!F4,0),if($R$8=true, ElantrisMaximums!F4,0),if($R$9=true, WorldhopperMaximums!F4,0)),")") -> 4 (2-13) | H4: =CONCATENATE(round(((if($R$5=true, StormlightAverages!G4,0)+if($R$6=true, MistbornAverages!G4,0)+if($R$7=true, WarbreakerAverages!G4,0)+if($R$8=true, ElantrisAverages!G4,0)+if($R$9=true, WorldhopperAverages!G4,0))/(if(countif($R$5:$R$9,true)=0, 1, COUNTIF($R$5:$R$9,true)))),0)," (",min(if($R$5=true, StormlightMinimums!G4,100000000000),if($R$6=true, MistbornMinimums!G4,100000000000),if($R$7=true, WarbreakerMinimums!G4,100000000000),if($R$8=true, ElantrisMinimums!G4,100000000000),if($R$9=true, WorldhopperMinimums!G4,100000000000)), ,"-",max(if($R$5=true,StormlightMaximums!G4,0),if($R$6=true,MistbornMaximums!G4,0),if($R$7=true, WarbreakerMaximums!G4,0),if($R$8=true, ElantrisMaximums!G4,0),if($R$9=true, WorldhopperMaximums!G4,0)),")") -> 0 (0-0) | I4: =CONCATENATE(round(((if($R$5=true, StormlightAverages!H4,0)+if($R$6=true, MistbornAverages!H4,0)+if($R$7=true, WarbreakerAverages!H4,0)+if($R$8=true, ElantrisAverages!H4,0)+if($R$9=true, WorldhopperAverages!H4,0))/(if(countif($R$5:$R$9,true)=0, 1, COUNTIF($R$5:$R$9,true)))),0)," (",min(if($R$5=true, StormlightMinimums!H4,100000000000),if($R$6=true, MistbornMinimums!H4,100000000000),if($R$7=true, WarbreakerMinimums!H4,100000000000),if($R$8=true, ElantrisMinimums!H4,100000000000),if($R$9=true, WorldhopperMinimums!H4,100000000000)), ,"-",max(if($R$5=true,StormlightMaximums!H4,0),if($R$6=true,MistbornMaximums!H4,0),if($R$7=true, WarbreakerMaximums!H4,0),if($R$8=true, ElantrisMaximums!H4,0),if($R$9=true, WorldhopperMaximums!H4,0)),")") -> 7 (1-11) | J4: =CONCATENATE(round(((if($R$5=true, StormlightAverages!I4,0)+if($R$6=true, MistbornAverages!I4,0)+if($R$7=true, WarbreakerAverages!I4,0)+if($R$8=true, ElantrisAverages!I4,0)+if($R$9=true, WorldhopperAverages!I4,0))/(if(countif($R$5:$R$9,true)=0, 1, COUNTIF($R$5:$R$9,true)))),0)," (",min(if($R$5=true, StormlightMinimums!I4,100000000000),if($R$6=true, MistbornMinimums!I4,100000000000),if($R$7=true, WarbreakerMinimums!I4,100000000000),if($R$8=true, ElantrisMinimums!I4,100000000000),if($R$9=true, WorldhopperMinimums!I4,100000000000)), ,"-",max(if($R$5=true,StormlightMaximums!I4,0),if($R$6=true,MistbornMaximums!I4,0),if($R$7=true, WarbreakerMaximums!I4,0),if($R$8=true, ElantrisMaximums!I4,0),if($R$9=true, WorldhopperMaximums!I4,0)),")") -> 2 (0-5) | ... L4: =CONCATENATE(round(((if($R$5=true, StormlightAverages!K4,0)+if($R$6=true, MistbornAverages!K4,0)+if($R$7=true, WarbreakerAverages!K4,0)+if($R$8=true, ElantrisAverages!K4,0)+if($R$9=true, WorldhopperAverages!K4,0))/(if(countif($R$5:$R$9,true)=0, 1, COUNTIF($R$5:$R$9,true)))),0)," (",min(if($R$5=true, StormlightMinimums!K4,100000000000),if($R$6=true, MistbornMinimums!K4,100000000000),if($R$7=true, WarbreakerMinimums!K4,100000000000),if($R$8=true, ElantrisMinimums!K4,100000000000),if($R$9=true, WorldhopperMinimums!K4,100000000000)), ,"-",max(if($R$5=true,StormlightMaximums!K4,0),if($R$6=true,MistbornMaximums!K4,0),if($R$7=true, WarbreakerMaximums!K4,0),if($R$8=true, ElantrisMaximums!K4,0),if($R$9=true, WorldhopperMaximums!K4,0)),")") -> 0 (0-0) | M4: =CONCATENATE(round(((if($R$5=true, StormlightAverages!M4,0)+if($R$6=true, MistbornAverages!M4,0)+if($R$7=true, WarbreakerAverages!M4,0)+if($R$8=true, ElantrisAverages!M4,0)+if($R$9=true, WorldhopperAverages!M4,0))/(if(countif($R$5:$R$9,true)=0, 1, COUNTIF($R$5:$R$9,true)))),0)," (",min(if($R$5=true, StormlightMinimums!L4,100000000000),if($R$6=true, MistbornMinimums!L4,100000000000),if($R$7=true, WarbreakerMinimums!L4,100000000000),if($R$8=true, ElantrisMinimums!L4,100000000000),if($R$9=true, WorldhopperMinimums!L4,100000000000)), ,"-",max(if($R$5=true,StormlightMaximums!L4,0),if($R$6=true,MistbornMaximums!L4,0),if($R$7=true, WarbreakerMaximums!L4,0),if($R$8=true, ElantrisMaximums!L4,0),if($R$9=true, WorldhopperMaximums!L4,0)),")") -> 3 (1-4) | N4: =CONCATENATE(round(((if($R$5=true, StormlightAverages!N4,0)+if($R$6=true, MistbornAverages!N4,0)+if($R$7=true, WarbreakerAverages!N4,0)+if($R$8=true, ElantrisAverages!N4,0)+if($R$9=true, WorldhopperAverages!N4,0))/(if(countif($R$5:$R$9,true)=0, 1, COUNTIF($R$5:$R$9,true)))),0)," (",min(if($R$5=true, StormlightMinimums!M4,100000000000),if($R$6=true, MistbornMinimums!M4,100000000000),if($R$7=true, WarbreakerMinimums!M4,100000000000),if($R$8=true, ElantrisMinimums!M4,100000000000),if($R$9=true, WorldhopperMinimums!M4,100000000000)), ,"-",max(if($R$5=true,StormlightMaximums!M4,0),if($R$6=true,MistbornMaximums!M4,0),if($R$7=true, WarbreakerMaximums!M4,0),if($R$8=true, ElantrisMaximums!M4,0),if($R$9=true, WorldhopperMaximums!M4,0)),")") -> 7 (3-12) | O4: =CONCATENATE(round(((if($R$5=true, StormlightAverages!O4,0)+if($R$6=true, MistbornAverages!O4,0)+if($R$7=true, WarbreakerAverages!O4,0)+if($R$8=true, ElantrisAverages!O4,0)+if($R$9=true, WorldhopperAverages!O4,0))/(if(countif($R$5:$R$9,true)=0, 1, COUNTIF($R$5:$R$9,true)))),0)," (",min(if($R$5=true, StormlightMinimums!N4,100000000000),if($R$6=true, MistbornMinimums!N4,100000000000),if($R$7=true, WarbreakerMinimums!N4,100000000000),if($R$8=true, ElantrisMinimums!N4,100000000000),if($R$9=true, WorldhopperMinimums!N4,100000000000)), ,"-",max(if($R$5=true,StormlightMaximums!N4,0),if($R$6=true,MistbornMaximums!N4,0),if($R$7=true, WarbreakerMaximums!N4,0),if($R$8=true, ElantrisMaximums!N4,0),if($R$9=true, WorldhopperMaximums!N4,0)),")") -> 7 (3-12) | Q4: Key | R4: Average (Max - Min)
A5: 1 | B5: Rival | C5: =CONCATENATE(round(((if($R$5=true, StormlightAverages!B5,0)+if($R$6=true, MistbornAverages!B5,0)+if($R$7=true, WarbreakerAverages!B5,0)+if($R$8=true, ElantrisAverages!B5,0)+if($R$9=true, WorldhopperAverages!B5,0))/(if(countif($R$5:$R$9,true)=0, 1, COUNTIF($R$5:$R$9,true)))),0)," (",min(if($R$5=true, StormlightMinimums!B5,100000000000),if($R$6=true, MistbornMinimums!B5,100000000000),if($R$7=true, WarbreakerMinimums!B5,100000000000),if($R$8=true, ElantrisMinimums!B5,100000000000),if($R$9=true, WorldhopperMinimums!B5,100000000000)), ,"-",max(if($R$5=true,StormlightMaximums!B5,0),if($R$6=true,MistbornMaximums!B5,0),if($R$7=true, WarbreakerMaximums!B5,0),if($R$8=true, ElantrisMaximums!B5,0),if($R$9=true, WorldhopperMaximums!B5,0)),")") -> 14 (12-16) | D5: =CONCATENATE(round(((if($R$5=true, StormlightAverages!C5,0)+if($R$6=true, MistbornAverages!C5,0)+if($R$7=true, WarbreakerAverages!C5,0)+if($R$8=true, ElantrisAverages!C5,0)+if($R$9=true, WorldhopperAverages!C5,0))/(if(countif($R$5:$R$9,true)=0, 1, COUNTIF($R$5:$R$9,true)))),0)," (",min(if($R$5=true, StormlightMinimums!C5,100000000000),if($R$6=true, MistbornMinimums!C5,100000000000),if($R$7=true, WarbreakerMinimums!C5,100000000000),if($R$8=true, ElantrisMinimums!C5,100000000000),if($R$9=true, WorldhopperMinimums!C5,100000000000)), ,"-",max(if($R$5=true,StormlightMaximums!C5,0),if($R$6=true,MistbornMaximums!C5,0),if($R$7=true, WarbreakerMaximums!C5,0),if($R$8=true, ElantrisMaximums!C5,0),if($R$9=true, WorldhopperMaximums!C5,0)),")") -> 13 (11-15) | E5: =CONCATENATE(round(((if($R$5=true, StormlightAverages!D5,0)+if($R$6=true, MistbornAverages!D5,0)+if($R$7=true, WarbreakerAverages!D5,0)+if($R$8=true, ElantrisAverages!D5,0)+if($R$9=true, WorldhopperAverages!D5,0))/(if(countif($R$5:$R$9,true)=0, 1, COUNTIF($R$5:$R$9,true)))),0)," (",min(if($R$5=true, StormlightMinimums!D5,100000000000),if($R$6=true, MistbornMinimums!D5,100000000000),if($R$7=true, WarbreakerMinimums!D5,100000000000),if($R$8=true, ElantrisMinimums!D5,100000000000),if($R$9=true, WorldhopperMinimums!D5,100000000000)), ,"-",max(if($R$5=true,StormlightMaximums!D5,0),if($R$6=true,MistbornMaximums!D5,0),if($R$7=true, WarbreakerMaximums!D5,0),if($R$8=true, ElantrisMaximums!D5,0),if($R$9=true, WorldhopperMaximums!D5,0)),")") -> 14 (12-16) | F5: =CONCATENATE(round(((if($R$5=true, StormlightAverages!E5,0)+if($R$6=true, MistbornAverages!E5,0)+if($R$7=true, WarbreakerAverages!E5,0)+if($R$8=true, ElantrisAverages!E5,0)+if($R$9=true, WorldhopperAverages!E5,0))/(if(countif($R$5:$R$9,true)=0, 1, COUNTIF($R$5:$R$9,true)))),0)," (",min(if($R$5=true, StormlightMinimums!E5,100000000000),if($R$6=true, MistbornMinimums!E5,100000000000),if($R$7=true, WarbreakerMinimums!E5,100000000000),if($R$8=true, ElantrisMinimums!E5,100000000000),if($R$9=true, WorldhopperMinimums!E5,100000000000)), ,"-",max(if($R$5=true,StormlightMaximums!E5,0),if($R$6=true,MistbornMaximums!E5,0),if($R$7=true, WarbreakerMaximums!E5,0),if($R$8=true, ElantrisMaximums!E5,0),if($R$9=true, WorldhopperMaximums!E5,0)),")") -> 22 (10-34) | G5: =CONCATENATE(round(((if($R$5=true, StormlightAverages!F5,0)+if($R$6=true, MistbornAverages!F5,0)+if($R$7=true, WarbreakerAverages!F5,0)+if($R$8=true, ElantrisAverages!F5,0)+if($R$9=true, WorldhopperAverages!F5,0))/(if(countif($R$5:$R$9,true)=0, 1, COUNTIF($R$5:$R$9,true)))),0)," (",min(if($R$5=true, StormlightMinimums!F5,100000000000),if($R$6=true, MistbornMinimums!F5,100000000000),if($R$7=true, WarbreakerMinimums!F5,100000000000),if($R$8=true, ElantrisMinimums!F5,100000000000),if($R$9=true, WorldhopperMinimums!F5,100000000000)), ,"-",max(if($R$5=true,StormlightMaximums!F5,0),if($R$6=true,MistbornMaximums!F5,0),if($R$7=true, WarbreakerMaximums!F5,0),if($R$8=true, ElantrisMaximums!F5,0),if($R$9=true, WorldhopperMaximums!F5,0)),")") -> 4 (2-5) | H5: =CONCATENATE(round(((if($R$5=true, StormlightAverages!G5,0)+if($R$6=true, MistbornAverages!G5,0)+if($R$7=true, WarbreakerAverages!G5,0)+if($R$8=true, ElantrisAverages!G5,0)+if($R$9=true, WorldhopperAverages!G5,0))/(if(countif($R$5:$R$9,true)=0, 1, COUNTIF($R$5:$R$9,true)))),0)," (",min(if($R$5=true, StormlightMinimums!G5,100000000000),if($R$6=true, MistbornMinimums!G5,100000000000),if($R$7=true, WarbreakerMinimums!G5,100000000000),if($R$8=true, ElantrisMinimums!G5,100000000000),if($R$9=true, WorldhopperMinimums!G5,100000000000)), ,"-",max(if($R$5=true,StormlightMaximums!G5,0),if($R$6=true,MistbornMaximums!G5,0),if($R$7=true, WarbreakerMaximums!G5,0),if($R$8=true, ElantrisMaximums!G5,0),if($R$9=true, WorldhopperMaximums!G5,0)),")") -> 1 (0-5) | I5: =CONCATENATE(round(((if($R$5=true, StormlightAverages!H5,0)+if($R$6=true, MistbornAverages!H5,0)+if($R$7=true, WarbreakerAverages!H5,0)+if($R$8=true, ElantrisAverages!H5,0)+if($R$9=true, WorldhopperAverages!H5,0))/(if(countif($R$5:$R$9,true)=0, 1, COUNTIF($R$5:$R$9,true)))),0)," (",min(if($R$5=true, StormlightMinimums!H5,100000000000),if($R$6=true, MistbornMinimums!H5,100000000000),if($R$7=true, WarbreakerMinimums!H5,100000000000),if($R$8=true, ElantrisMinimums!H5,100000000000),if($R$9=true, WorldhopperMinimums!H5,100000000000)), ,"-",max(if($R$5=true,StormlightMaximums!H5,0),if($R$6=true,MistbornMaximums!H5,0),if($R$7=true, WarbreakerMaximums!H5,0),if($R$8=true, ElantrisMaximums!H5,0),if($R$9=true, WorldhopperMaximums!H5,0)),")") -> 12 (5-20) | J5: =CONCATENATE(round(((if($R$5=true, StormlightAverages!I5,0)+if($R$6=true, MistbornAverages!I5,0)+if($R$7=true, WarbreakerAverages!I5,0)+if($R$8=true, ElantrisAverages!I5,0)+if($R$9=true, WorldhopperAverages!I5,0))/(if(countif($R$5:$R$9,true)=0, 1, COUNTIF($R$5:$R$9,true)))),0)," (",min(if($R$5=true, StormlightMinimums!I5,100000000000),if($R$6=true, MistbornMinimums!I5,100000000000),if($R$7=true, WarbreakerMinimums!I5,100000000000),if($R$8=true, ElantrisMinimums!I5,100000000000),if($R$9=true, WorldhopperMinimums!I5,100000000000)), ,"-",max(if($R$5=true,StormlightMaximums!I5,0),if($R$6=true,MistbornMaximums!I5,0),if($R$7=true, WarbreakerMaximums!I5,0),if($R$8=true, ElantrisMaximums!I5,0),if($R$9=true, WorldhopperMaximums!I5,0)),")") -> 5 (0-13) | ... L5: =CONCATENATE(round(((if($R$5=true, StormlightAverages!K5,0)+if($R$6=true, MistbornAverages!K5,0)+if($R$7=true, WarbreakerAverages!K5,0)+if($R$8=true, ElantrisAverages!K5,0)+if($R$9=true, WorldhopperAverages!K5,0))/(if(countif($R$5:$R$9,true)=0, 1, COUNTIF($R$5:$R$9,true)))),0)," (",min(if($R$5=true, StormlightMinimums!K5,100000000000),if($R$6=true, MistbornMinimums!K5,100000000000),if($R$7=true, WarbreakerMinimums!K5,100000000000),if($R$8=true, ElantrisMinimums!K5,100000000000),if($R$9=true, WorldhopperMinimums!K5,100000000000)), ,"-",max(if($R$5=true,StormlightMaximums!K5,0),if($R$6=true,MistbornMaximums!K5,0),if($R$7=true, WarbreakerMaximums!K5,0),if($R$8=true, ElantrisMaximums!K5,0),if($R$9=true, WorldhopperMaximums!K5,0)),")") -> 9 (9-9) | M5: =CONCATENATE(round(((if($R$5=true, StormlightAverages!M5,0)+if($R$6=true, MistbornAverages!M5,0)+if($R$7=true, WarbreakerAverages!M5,0)+if($R$8=true, ElantrisAverages!M5,0)+if($R$9=true, WorldhopperAverages!M5,0))/(if(countif($R$5:$R$9,true)=0, 1, COUNTIF($R$5:$R$9,true)))),0)," (",min(if($R$5=true, StormlightMinimums!L5,100000000000),if($R$6=true, MistbornMinimums!L5,100000000000),if($R$7=true, WarbreakerMinimums!L5,100000000000),if($R$8=true, ElantrisMinimums!L5,100000000000),if($R$9=true, WorldhopperMinimums!L5,100000000000)), ,"-",max(if($R$5=true,StormlightMaximums!L5,0),if($R$6=true,MistbornMaximums!L5,0),if($R$7=true, WarbreakerMaximums!L5,0),if($R$8=true, ElantrisMaximums!L5,0),if($R$9=true, WorldhopperMaximums!L5,0)),")") -> 4 (1-6) | N5: =CONCATENATE(round(((if($R$5=true, StormlightAverages!N5,0)+if($R$6=true, MistbornAverages!N5,0)+if($R$7=true, WarbreakerAverages!N5,0)+if($R$8=true, ElantrisAverages!N5,0)+if($R$9=true, WorldhopperAverages!N5,0))/(if(countif($R$5:$R$9,true)=0, 1, COUNTIF($R$5:$R$9,true)))),0)," (",min(if($R$5=true, StormlightMinimums!M5,100000000000),if($R$6=true, MistbornMinimums!M5,100000000000),if($R$7=true, WarbreakerMinimums!M5,100000000000),if($R$8=true, ElantrisMinimums!M5,100000000000),if($R$9=true, WorldhopperMinimums!M5,100000000000)), ,"-",max(if($R$5=true,StormlightMaximums!M5,0),if($R$6=true,MistbornMaximums!M5,0),if($R$7=true, WarbreakerMaximums!M5,0),if($R$8=true, ElantrisMaximums!M5,0),if($R$9=true, WorldhopperMaximums!M5,0)),")") -> 12 (3-24) | O5: =CONCATENATE(round(((if($R$5=true, StormlightAverages!O5,0)+if($R$6=true, MistbornAverages!O5,0)+if($R$7=true, WarbreakerAverages!O5,0)+if($R$8=true, ElantrisAverages!O5,0)+if($R$9=true, WorldhopperAverages!O5,0))/(if(countif($R$5:$R$9,true)=0, 1, COUNTIF($R$5:$R$9,true)))),0)," (",min(if($R$5=true, StormlightMinimums!N5,100000000000),if($R$6=true, MistbornMinimums!N5,100000000000),if($R$7=true, WarbreakerMinimums!N5,100000000000),if($R$8=true, ElantrisMinimums!N5,100000000000),if($R$9=true, WorldhopperMinimums!N5,100000000000)), ,"-",max(if($R$5=true,StormlightMaximums!N5,0),if($R$6=true,MistbornMaximums!N5,0),if($R$7=true, WarbreakerMaximums!N5,0),if($R$8=true, ElantrisMaximums!N5,0),if($R$9=true, WorldhopperMaximums!N5,0)),")") -> 15 (3-24) | Q5: Stormlight | R5: TRUE
A6: 1 | B6: Boss | C6: =CONCATENATE(round(((if($R$5=true, StormlightAverages!B6,0)+if($R$6=true, MistbornAverages!B6,0)+if($R$7=true, WarbreakerAverages!B6,0)+if($R$8=true, ElantrisAverages!B6,0)+if($R$9=true, WorldhopperAverages!B6,0))/(if(countif($R$5:$R$9,true)=0, 1, COUNTIF($R$5:$R$9,true)))),0)," (",min(if($R$5=true, StormlightMinimums!B6,100000000000),if($R$6=true, MistbornMinimums!B6,100000000000),if($R$7=true, WarbreakerMinimums!B6,100000000000),if($R$8=true, ElantrisMinimums!B6,100000000000),if($R$9=true, WorldhopperMinimums!B6,100000000000)), ,"-",max(if($R$5=true,StormlightMaximums!B6,0),if($R$6=true,MistbornMaximums!B6,0),if($R$7=true, WarbreakerMaximums!B6,0),if($R$8=true, ElantrisMaximums!B6,0),if($R$9=true, WorldhopperMaximums!B6,0)),")") -> 15 (14-15) | D6: =CONCATENATE(round(((if($R$5=true, StormlightAverages!C6,0)+if($R$6=true, MistbornAverages!C6,0)+if($R$7=true, WarbreakerAverages!C6,0)+if($R$8=true, ElantrisAverages!C6,0)+if($R$9=true, WorldhopperAverages!C6,0))/(if(countif($R$5:$R$9,true)=0, 1, COUNTIF($R$5:$R$9,true)))),0)," (",min(if($R$5=true, StormlightMinimums!C6,100000000000),if($R$6=true, MistbornMinimums!C6,100000000000),if($R$7=true, WarbreakerMinimums!C6,100000000000),if($R$8=true, ElantrisMinimums!C6,100000000000),if($R$9=true, WorldhopperMinimums!C6,100000000000)), ,"-",max(if($R$5=true,StormlightMaximums!C6,0),if($R$6=true,MistbornMaximums!C6,0),if($R$7=true, WarbreakerMaximums!C6,0),if($R$8=true, ElantrisMaximums!C6,0),if($R$9=true, WorldhopperMaximums!C6,0)),")") -> 15 (12-17) | E6: =CONCATENATE(round(((if($R$5=true, StormlightAverages!D6,0)+if($R$6=true, MistbornAverages!D6,0)+if($R$7=true, WarbreakerAverages!D6,0)+if($R$8=true, ElantrisAverages!D6,0)+if($R$9=true, WorldhopperAverages!D6,0))/(if(countif($R$5:$R$9,true)=0, 1, COUNTIF($R$5:$R$9,true)))),0)," (",min(if($R$5=true, StormlightMinimums!D6,100000000000),if($R$6=true, MistbornMinimums!D6,100000000000),if($R$7=true, WarbreakerMinimums!D6,100000000000),if($R$8=true, ElantrisMinimums!D6,100000000000),if($R$9=true, WorldhopperMinimums!D6,100000000000)), ,"-",max(if($R$5=true,StormlightMaximums!D6,0),if($R$6=true,MistbornMaximums!D6,0),if($R$7=true, WarbreakerMaximums!D6,0),if($R$8=true, ElantrisMaximums!D6,0),if($R$9=true, WorldhopperMaximums!D6,0)),")") -> 16 (15-17) | F6: =CONCATENATE(round(((if($R$5=true, StormlightAverages!E6,0)+if($R$6=true, MistbornAverages!E6,0)+if($R$7=true, WarbreakerAverages!E6,0)+if($R$8=true, ElantrisAverages!E6,0)+if($R$9=true, WorldhopperAverages!E6,0))/(if(countif($R$5:$R$9,true)=0, 1, COUNTIF($R$5:$R$9,true)))),0)," (",min(if($R$5=true, StormlightMinimums!E6,100000000000),if($R$6=true, MistbornMinimums!E6,100000000000),if($R$7=true, WarbreakerMinimums!E6,100000000000),if($R$8=true, ElantrisMinimums!E6,100000000000),if($R$9=true, WorldhopperMinimums!E6,100000000000)), ,"-",max(if($R$5=true,StormlightMaximums!E6,0),if($R$6=true,MistbornMaximums!E6,0),if($R$7=true, WarbreakerMaximums!E6,0),if($R$8=true, ElantrisMaximums!E6,0),if($R$9=true, WorldhopperMaximums!E6,0)),")") -> 57 (40-80) | G6: =CONCATENATE(round(((if($R$5=true, StormlightAverages!F6,0)+if($R$6=true, MistbornAverages!F6,0)+if($R$7=true, WarbreakerAverages!F6,0)+if($R$8=true, ElantrisAverages!F6,0)+if($R$9=true, WorldhopperAverages!F6,0))/(if(countif($R$5:$R$9,true)=0, 1, COUNTIF($R$5:$R$9,true)))),0)," (",min(if($R$5=true, StormlightMinimums!F6,100000000000),if($R$6=true, MistbornMinimums!F6,100000000000),if($R$7=true, WarbreakerMinimums!F6,100000000000),if($R$8=true, ElantrisMinimums!F6,100000000000),if($R$9=true, WorldhopperMinimums!F6,100000000000)), ,"-",max(if($R$5=true,StormlightMaximums!F6,0),if($R$6=true,MistbornMaximums!F6,0),if($R$7=true, WarbreakerMaximums!F6,0),if($R$8=true, ElantrisMaximums!F6,0),if($R$9=true, WorldhopperMaximums!F6,0)),")") -> 5 (3-6) | H6: =CONCATENATE(round(((if($R$5=true, StormlightAverages!G6,0)+if($R$6=true, MistbornAverages!G6,0)+if($R$7=true, WarbreakerAverages!G6,0)+if($R$8=true, ElantrisAverages!G6,0)+if($R$9=true, WorldhopperAverages!G6,0))/(if(countif($R$5:$R$9,true)=0, 1, COUNTIF($R$5:$R$9,true)))),0)," (",min(if($R$5=true, StormlightMinimums!G6,100000000000),if($R$6=true, MistbornMinimums!G6,100000000000),if($R$7=true, WarbreakerMinimums!G6,100000000000),if($R$8=true, ElantrisMinimums!G6,100000000000),if($R$9=true, WorldhopperMinimums!G6,100000000000)), ,"-",max(if($R$5=true,StormlightMaximums!G6,0),if($R$6=true,MistbornMaximums!G6,0),if($R$7=true, WarbreakerMaximums!G6,0),if($R$8=true, ElantrisMaximums!G6,0),if($R$9=true, WorldhopperMaximums!G6,0)),")") -> 2 (0-6) | I6: =CONCATENATE(round(((if($R$5=true, StormlightAverages!H6,0)+if($R$6=true, MistbornAverages!H6,0)+if($R$7=true, WarbreakerAverages!H6,0)+if($R$8=true, ElantrisAverages!H6,0)+if($R$9=true, WorldhopperAverages!H6,0))/(if(countif($R$5:$R$9,true)=0, 1, COUNTIF($R$5:$R$9,true)))),0)," (",min(if($R$5=true, StormlightMinimums!H6,100000000000),if($R$6=true, MistbornMinimums!H6,100000000000),if($R$7=true, WarbreakerMinimums!H6,100000000000),if($R$8=true, ElantrisMinimums!H6,100000000000),if($R$9=true, WorldhopperMinimums!H6,100000000000)), ,"-",max(if($R$5=true,StormlightMaximums!H6,0),if($R$6=true,MistbornMaximums!H6,0),if($R$7=true, WarbreakerMaximums!H6,0),if($R$8=true, ElantrisMaximums!H6,0),if($R$9=true, WorldhopperMaximums!H6,0)),")") -> 9 (5-11) | J6: =CONCATENATE(round(((if($R$5=true, StormlightAverages!I6,0)+if($R$6=true, MistbornAverages!I6,0)+if($R$7=true, WarbreakerAverages!I6,0)+if($R$8=true, ElantrisAverages!I6,0)+if($R$9=true, WorldhopperAverages!I6,0))/(if(countif($R$5:$R$9,true)=0, 1, COUNTIF($R$5:$R$9,true)))),0)," (",min(if($R$5=true, StormlightMinimums!I6,100000000000),if($R$6=true, MistbornMinimums!I6,100000000000),if($R$7=true, WarbreakerMinimums!I6,100000000000),if($R$8=true, ElantrisMinimums!I6,100000000000),if($R$9=true, WorldhopperMinimums!I6,100000000000)), ,"-",max(if($R$5=true,StormlightMaximums!I6,0),if($R$6=true,MistbornMaximums!I6,0),if($R$7=true, WarbreakerMaximums!I6,0),if($R$8=true, ElantrisMaximums!I6,0),if($R$9=true, WorldhopperMaximums!I6,0)),")") -> 12 (3-20) | ... L6: =CONCATENATE(round(((if($R$5=true, StormlightAverages!K6,0)+if($R$6=true, MistbornAverages!K6,0)+if($R$7=true, WarbreakerAverages!K6,0)+if($R$8=true, ElantrisAverages!K6,0)+if($R$9=true, WorldhopperAverages!K6,0))/(if(countif($R$5:$R$9,true)=0, 1, COUNTIF($R$5:$R$9,true)))),0)," (",min(if($R$5=true, StormlightMinimums!K6,100000000000),if($R$6=true, MistbornMinimums!K6,100000000000),if($R$7=true, WarbreakerMinimums!K6,100000000000),if($R$8=true, ElantrisMinimums!K6,100000000000),if($R$9=true, WorldhopperMinimums!K6,100000000000)), ,"-",max(if($R$5=true,StormlightMaximums!K6,0),if($R$6=true,MistbornMaximums!K6,0),if($R$7=true, WarbreakerMaximums!K6,0),if($R$8=true, ElantrisMaximums!K6,0),if($R$9=true, WorldhopperMaximums!K6,0)),")") -> 22 (22-22) | M6: =CONCATENATE(round(((if($R$5=true, StormlightAverages!M6,0)+if($R$6=true, MistbornAverages!M6,0)+if($R$7=true, WarbreakerAverages!M6,0)+if($R$8=true, ElantrisAverages!M6,0)+if($R$9=true, WorldhopperAverages!M6,0))/(if(countif($R$5:$R$9,true)=0, 1, COUNTIF($R$5:$R$9,true)))),0)," (",min(if($R$5=true, StormlightMinimums!L6,100000000000),if($R$6=true, MistbornMinimums!L6,100000000000),if($R$7=true, WarbreakerMinimums!L6,100000000000),if($R$8=true, ElantrisMinimums!L6,100000000000),if($R$9=true, WorldhopperMinimums!L6,100000000000)), ,"-",max(if($R$5=true,StormlightMaximums!L6,0),if($R$6=true,MistbornMaximums!L6,0),if($R$7=true, WarbreakerMaximums!L6,0),if($R$8=true, ElantrisMaximums!L6,0),if($R$9=true, WorldhopperMaximums!L6,0)),")") -> 5 (3-6) | N6: =CONCATENATE(round(((if($R$5=true, StormlightAverages!N6,0)+if($R$6=true, MistbornAverages!N6,0)+if($R$7=true, WarbreakerAverages!N6,0)+if($R$8=true, ElantrisAverages!N6,0)+if($R$9=true, WorldhopperAverages!N6,0))/(if(countif($R$5:$R$9,true)=0, 1, COUNTIF($R$5:$R$9,true)))),0)," (",min(if($R$5=true, StormlightMinimums!M6,100000000000),if($R$6=true, MistbornMinimums!M6,100000000000),if($R$7=true, WarbreakerMinimums!M6,100000000000),if($R$8=true, ElantrisMinimums!M6,100000000000),if($R$9=true, WorldhopperMinimums!M6,100000000000)), ,"-",max(if($R$5=true,StormlightMaximums!M6,0),if($R$6=true,MistbornMaximums!M6,0),if($R$7=true, WarbreakerMaximums!M6,0),if($R$8=true, ElantrisMaximums!M6,0),if($R$9=true, WorldhopperMaximums!M6,0)),")") -> 16 (9-25) | O6: =CONCATENATE(round(((if($R$5=true, StormlightAverages!O6,0)+if($R$6=true, MistbornAverages!O6,0)+if($R$7=true, WarbreakerAverages!O6,0)+if($R$8=true, ElantrisAverages!O6,0)+if($R$9=true, WorldhopperAverages!O6,0))/(if(countif($R$5:$R$9,true)=0, 1, COUNTIF($R$5:$R$9,true)))),0)," (",min(if($R$5=true, StormlightMinimums!N6,100000000000),if($R$6=true, MistbornMinimums!N6,100000000000),if($R$7=true, WarbreakerMinimums!N6,100000000000),if($R$8=true, ElantrisMinimums!N6,100000000000),if($R$9=true, WorldhopperMinimums!N6,100000000000)), ,"-",max(if($R$5=true,StormlightMaximums!N6,0),if($R$6=true,MistbornMaximums!N6,0),if($R$7=true, WarbreakerMaximums!N6,0),if($R$8=true, ElantrisMaximums!N6,0),if($R$9=true, WorldhopperMaximums!N6,0)),")") -> 24 (9-49) | Q6: Mistborn | R6: FALSE | S6: Nonfunctioning! Do not Edit!
A7: 2 | B7: Minion | C7: =CONCATENATE(round(((if($R$5=true, StormlightAverages!B11,0)+if($R$6=true, MistbornAverages!B11,0)+if($R$7=true, WarbreakerAverages!B11,0)+if($R$8=true, ElantrisAverages!B11,0)+if($R$9=true, WorldhopperAverages!B11,0))/(if(countif($R$5:$R$9,true)=0, 1, COUNTIF($R$5:$R$9,true)))),0)," (",min(if($R$5=true, StormlightMinimums!B11,100000000000),if($R$6=true, MistbornMinimums!B11,100000000000),if($R$7=true, WarbreakerMinimums!B11,100000000000),if($R$8=true, ElantrisMinimums!B11,100000000000),if($R$9=true, WorldhopperMinimums!B11,100000000000)), ,"-",max(if($R$5=true,StormlightMaximums!B11,0),if($R$6=true,MistbornMaximums!B11,0),if($R$7=true, WarbreakerMaximums!B11,0),if($R$8=true, ElantrisMaximums!B11,0),if($R$9=true, WorldhopperMaximums!B11,0)),")") -> 13 (11-15) | D7: =CONCATENATE(round(((if($R$5=true, StormlightAverages!C11,0)+if($R$6=true, MistbornAverages!C11,0)+if($R$7=true, WarbreakerAverages!C11,0)+if($R$8=true, ElantrisAverages!C11,0)+if($R$9=true, WorldhopperAverages!C11,0))/(if(countif($R$5:$R$9,true)=0, 1, COUNTIF($R$5:$R$9,true)))),0)," (",min(if($R$5=true, StormlightMinimums!C11,100000000000),if($R$6=true, MistbornMinimums!C11,100000000000),if($R$7=true, WarbreakerMinimums!C11,100000000000),if($R$8=true, ElantrisMinimums!C11,100000000000),if($R$9=true, WorldhopperMinimums!C11,100000000000)), ,"-",max(if($R$5=true,StormlightMaximums!C11,0),if($R$6=true,MistbornMaximums!C11,0),if($R$7=true, WarbreakerMaximums!C11,0),if($R$8=true, ElantrisMaximums!C11,0),if($R$9=true, WorldhopperMaximums!C11,0)),")") -> 14 (12-15) | E7: =CONCATENATE(round(((if($R$5=true, StormlightAverages!D11,0)+if($R$6=true, MistbornAverages!D11,0)+if($R$7=true, WarbreakerAverages!D11,0)+if($R$8=true, ElantrisAverages!D11,0)+if($R$9=true, WorldhopperAverages!D11,0))/(if(countif($R$5:$R$9,true)=0, 1, COUNTIF($R$5:$R$9,true)))),0)," (",min(if($R$5=true, StormlightMinimums!D11,100000000000),if($R$6=true, MistbornMinimums!D11,100000000000),if($R$7=true, WarbreakerMinimums!D11,100000000000),if($R$8=true, ElantrisMinimums!D11,100000000000),if($R$9=true, WorldhopperMinimums!D11,100000000000)), ,"-",max(if($R$5=true,StormlightMaximums!D11,0),if($R$6=true,MistbornMaximums!D11,0),if($R$7=true, WarbreakerMaximums!D11,0),if($R$8=true, ElantrisMaximums!D11,0),if($R$9=true, WorldhopperMaximums!D11,0)),")") -> 16 (14-18) | F7: =CONCATENATE(round(((if($R$5=true, StormlightAverages!E11,0)+if($R$6=true, MistbornAverages!E11,0)+if($R$7=true, WarbreakerAverages!E11,0)+if($R$8=true, ElantrisAverages!E11,0)+if($R$9=true, WorldhopperAverages!E11,0))/(if(countif($R$5:$R$9,true)=0, 1, COUNTIF($R$5:$R$9,true)))),0)," (",min(if($R$5=true, StormlightMinimums!E11,100000000000),if($R$6=true, MistbornMinimums!E11,100000000000),if($R$7=true, WarbreakerMinimums!E11,100000000000),if($R$8=true, ElantrisMinimums!E11,100000000000),if($R$9=true, WorldhopperMinimums!E11,100000000000)), ,"-",max(if($R$5=true,StormlightMaximums!E11,0),if($R$6=true,MistbornMaximums!E11,0),if($R$7=true, WarbreakerMaximums!E11,0),if($R$8=true, ElantrisMaximums!E11,0),if($R$9=true, WorldhopperMaximums!E11,0)),")") -> 21 (18-24) | G7: =CONCATENATE(round(((if($R$5=true, StormlightAverages!F11,0)+if($R$6=true, MistbornAverages!F11,0)+if($R$7=true, WarbreakerAverages!F11,0)+if($R$8=true, ElantrisAverages!F11,0)+if($R$9=true, WorldhopperAverages!F11,0))/(if(countif($R$5:$R$9,true)=0, 1, COUNTIF($R$5:$R$9,true)))),0)," (",min(if($R$5=true, StormlightMinimums!F11,100000000000),if($R$6=true, MistbornMinimums!F11,100000000000),if($R$7=true, WarbreakerMinimums!F11,100000000000),if($R$8=true, ElantrisMinimums!F11,100000000000),if($R$9=true, WorldhopperMinimums!F11,100000000000)), ,"-",max(if($R$5=true,StormlightMaximums!F11,0),if($R$6=true,MistbornMaximums!F11,0),if($R$7=true, WarbreakerMaximums!F11,0),if($R$8=true, ElantrisMaximums!F11,0),if($R$9=true, WorldhopperMaximums!F11,0)),")") -> 4 (3-4) | H7: =CONCATENATE(round(((if($R$5=true, StormlightAverages!G11,0)+if($R$6=true, MistbornAverages!G11,0)+if($R$7=true, WarbreakerAverages!G11,0)+if($R$8=true, ElantrisAverages!G11,0)+if($R$9=true, WorldhopperAverages!G11,0))/(if(countif($R$5:$R$9,true)=0, 1, COUNTIF($R$5:$R$9,true)))),0)," (",min(if($R$5=true, StormlightMinimums!G11,100000000000),if($R$6=true, MistbornMinimums!G11,100000000000),if($R$7=true, WarbreakerMinimums!G11,100000000000),if($R$8=true, ElantrisMinimums!G11,100000000000),if($R$9=true, WorldhopperMinimums!G11,100000000000)), ,"-",max(if($R$5=true,StormlightMaximums!G11,0),if($R$6=true,MistbornMaximums!G11,0),if($R$7=true, WarbreakerMaximums!G11,0),if($R$8=true, ElantrisMaximums!G11,0),if($R$9=true, WorldhopperMaximums!G11,0)),")") -> 3 (0-5) | I7: =CONCATENATE(round(((if($R$5=true, StormlightAverages!H11,0)+if($R$6=true, MistbornAverages!H11,0)+if($R$7=true, WarbreakerAverages!H11,0)+if($R$8=true, ElantrisAverages!H11,0)+if($R$9=true, WorldhopperAverages!H11,0))/(if(countif($R$5:$R$9,true)=0, 1, COUNTIF($R$5:$R$9,true)))),0)," (",min(if($R$5=true, StormlightMinimums!H11,100000000000),if($R$6=true, MistbornMinimums!H11,100000000000),if($R$7=true, WarbreakerMinimums!H11,100000000000),if($R$8=true, ElantrisMinimums!H11,100000000000),if($R$9=true, WorldhopperMinimums!H11,100000000000)), ,"-",max(if($R$5=true,StormlightMaximums!H11,0),if($R$6=true,MistbornMaximums!H11,0),if($R$7=true, WarbreakerMaximums!H11,0),if($R$8=true, ElantrisMaximums!H11,0),if($R$9=true, WorldhopperMaximums!H11,0)),")") -> 16 (4-28) | J7: =CONCATENATE(round(((if($R$5=true, StormlightAverages!I11,0)+if($R$6=true, MistbornAverages!I11,0)+if($R$7=true, WarbreakerAverages!I11,0)+if($R$8=true, ElantrisAverages!I11,0)+if($R$9=true, WorldhopperAverages!I11,0))/(if(countif($R$5:$R$9,true)=0, 1, COUNTIF($R$5:$R$9,true)))),0)," (",min(if($R$5=true, StormlightMinimums!I11,100000000000),if($R$6=true, MistbornMinimums!I11,100000000000),if($R$7=true, WarbreakerMinimums!I11,100000000000),if($R$8=true, ElantrisMinimums!I11,100000000000),if($R$9=true, WorldhopperMinimums!I11,100000000000)), ,"-",max(if($R$5=true,StormlightMaximums!I11,0),if($R$6=true,MistbornMaximums!I11,0),if($R$7=true, WarbreakerMaximums!I11,0),if($R$8=true, ElantrisMaximums!I11,0),if($R$9=true, WorldhopperMaximums!I11,0)),")") -> 2 (0-4) | ... L7: =CONCATENATE(round(((if($R$5=true, StormlightAverages!K11,0)+if($R$6=true, MistbornAverages!K11,0)+if($R$7=true, WarbreakerAverages!K11,0)+if($R$8=true, ElantrisAverages!K11,0)+if($R$9=true, WorldhopperAverages!K11,0))/(if(countif($R$5:$R$9,true)=0, 1, COUNTIF($R$5:$R$9,true)))),0)," (",min(if($R$5=true, StormlightMinimums!K11,100000000000),if($R$6=true, MistbornMinimums!K11,100000000000),if($R$7=true, WarbreakerMinimums!K11,100000000000),if($R$8=true, ElantrisMinimums!K11,100000000000),if($R$9=true, WorldhopperMinimums!K11,100000000000)), ,"-",max(if($R$5=true,StormlightMaximums!K11,0),if($R$6=true,MistbornMaximums!K11,0),if($R$7=true, WarbreakerMaximums!K11,0),if($R$8=true, ElantrisMaximums!K11,0),if($R$9=true, WorldhopperMaximums!K11,0)),")") -> 0 (0-0) | M7: =CONCATENATE(round(((if($R$5=true, StormlightAverages!M11,0)+if($R$6=true, MistbornAverages!M11,0)+if($R$7=true, WarbreakerAverages!M11,0)+if($R$8=true, ElantrisAverages!M11,0)+if($R$9=true, WorldhopperAverages!M11,0))/(if(countif($R$5:$R$9,true)=0, 1, COUNTIF($R$5:$R$9,true)))),0)," (",min(if($R$5=true, StormlightMinimums!L11,100000000000),if($R$6=true, MistbornMinimums!L11,100000000000),if($R$7=true, WarbreakerMinimums!L11,100000000000),if($R$8=true, ElantrisMinimums!L11,100000000000),if($R$9=true, WorldhopperMinimums!L11,100000000000)), ,"-",max(if($R$5=true,StormlightMaximums!L11,0),if($R$6=true,MistbornMaximums!L11,0),if($R$7=true, WarbreakerMaximums!L11,0),if($R$8=true, ElantrisMaximums!L11,0),if($R$9=true, WorldhopperMaximums!L11,0)),")") -> 6 (4-7) | N7: =CONCATENATE(round(((if($R$5=true, StormlightAverages!N11,0)+if($R$6=true, MistbornAverages!N11,0)+if($R$7=true, WarbreakerAverages!N11,0)+if($R$8=true, ElantrisAverages!N11,0)+if($R$9=true, WorldhopperAverages!N11,0))/(if(countif($R$5:$R$9,true)=0, 1, COUNTIF($R$5:$R$9,true)))),0)," (",min(if($R$5=true, StormlightMinimums!M11,100000000000),if($R$6=true, MistbornMinimums!M11,100000000000),if($R$7=true, WarbreakerMinimums!M11,100000000000),if($R$8=true, ElantrisMinimums!M11,100000000000),if($R$9=true, WorldhopperMinimums!M11,100000000000)), ,"-",max(if($R$5=true,StormlightMaximums!M11,0),if($R$6=true,MistbornMaximums!M11,0),if($R$7=true, WarbreakerMaximums!M11,0),if($R$8=true, ElantrisMaximums!M11,0),if($R$9=true, WorldhopperMaximums!M11,0)),")") -> 8 (7-9) | O7: =CONCATENATE(round(((if($R$5=true, StormlightAverages!O11,0)+if($R$6=true, MistbornAverages!O11,0)+if($R$7=true, WarbreakerAverages!O11,0)+if($R$8=true, ElantrisAverages!O11,0)+if($R$9=true, WorldhopperAverages!O11,0))/(if(countif($R$5:$R$9,true)=0, 1, COUNTIF($R$5:$R$9,true)))),0)," (",min(if($R$5=true, StormlightMinimums!N11,100000000000),if($R$6=true, MistbornMinimums!N11,100000000000),if($R$7=true, WarbreakerMinimums!N11,100000000000),if($R$8=true, ElantrisMinimums!N11,100000000000),if($R$9=true, WorldhopperMinimums!N11,100000000000)), ,"-",max(if($R$5=true,StormlightMaximums!N11,0),if($R$6=true,MistbornMaximums!N11,0),if($R$7=true, WarbreakerMaximums!N11,0),if($R$8=true, ElantrisMaximums!N11,0),if($R$9=true, WorldhopperMaximums!N11,0)),")") -> 10 (7-12) | Q7: Warbreaker | R7: FALSE
A8: 2 | B8: Rival | C8: =CONCATENATE(round(((if($R$5=true, StormlightAverages!B12,0)+if($R$6=true, MistbornAverages!B12,0)+if($R$7=true, WarbreakerAverages!B12,0)+if($R$8=true, ElantrisAverages!B12,0)+if($R$9=true, WorldhopperAverages!B12,0))/(if(countif($R$5:$R$9,true)=0, 1, COUNTIF($R$5:$R$9,true)))),0)," (",min(if($R$5=true, StormlightMinimums!B12,100000000000),if($R$6=true, MistbornMinimums!B12,100000000000),if($R$7=true, WarbreakerMinimums!B12,100000000000),if($R$8=true, ElantrisMinimums!B12,100000000000),if($R$9=true, WorldhopperMinimums!B12,100000000000)), ,"-",max(if($R$5=true,StormlightMaximums!B12,0),if($R$6=true,MistbornMaximums!B12,0),if($R$7=true, WarbreakerMaximums!B12,0),if($R$8=true, ElantrisMaximums!B12,0),if($R$9=true, WorldhopperMaximums!B12,0)),")") -> 16 (13-19) | D8: =CONCATENATE(round(((if($R$5=true, StormlightAverages!C12,0)+if($R$6=true, MistbornAverages!C12,0)+if($R$7=true, WarbreakerAverages!C12,0)+if($R$8=true, ElantrisAverages!C12,0)+if($R$9=true, WorldhopperAverages!C12,0))/(if(countif($R$5:$R$9,true)=0, 1, COUNTIF($R$5:$R$9,true)))),0)," (",min(if($R$5=true, StormlightMinimums!C12,100000000000),if($R$6=true, MistbornMinimums!C12,100000000000),if($R$7=true, WarbreakerMinimums!C12,100000000000),if($R$8=true, ElantrisMinimums!C12,100000000000),if($R$9=true, WorldhopperMinimums!C12,100000000000)), ,"-",max(if($R$5=true,StormlightMaximums!C12,0),if($R$6=true,MistbornMaximums!C12,0),if($R$7=true, WarbreakerMaximums!C12,0),if($R$8=true, ElantrisMaximums!C12,0),if($R$9=true, WorldhopperMaximums!C12,0)),")") -> 15 (11-19) | E8: =CONCATENATE(round(((if($R$5=true, StormlightAverages!D12,0)+if($R$6=true, MistbornAverages!D12,0)+if($R$7=true, WarbreakerAverages!D12,0)+if($R$8=true, ElantrisAverages!D12,0)+if($R$9=true, WorldhopperAverages!D12,0))/(if(countif($R$5:$R$9,true)=0, 1, COUNTIF($R$5:$R$9,true)))),0)," (",min(if($R$5=true, StormlightMinimums!D12,100000000000),if($R$6=true, MistbornMinimums!D12,100000000000),if($R$7=true, WarbreakerMinimums!D12,100000000000),if($R$8=true, ElantrisMinimums!D12,100000000000),if($R$9=true, WorldhopperMinimums!D12,100000000000)), ,"-",max(if($R$5=true,StormlightMaximums!D12,0),if($R$6=true,MistbornMaximums!D12,0),if($R$7=true, WarbreakerMaximums!D12,0),if($R$8=true, ElantrisMaximums!D12,0),if($R$9=true, WorldhopperMaximums!D12,0)),")") -> 15 (13-19) | F8: =CONCATENATE(round(((if($R$5=true, StormlightAverages!E12,0)+if($R$6=true, MistbornAverages!E12,0)+if($R$7=true, WarbreakerAverages!E12,0)+if($R$8=true, ElantrisAverages!E12,0)+if($R$9=true, WorldhopperAverages!E12,0))/(if(countif($R$5:$R$9,true)=0, 1, COUNTIF($R$5:$R$9,true)))),0)," (",min(if($R$5=true, StormlightMinimums!E12,100000000000),if($R$6=true, MistbornMinimums!E12,100000000000),if($R$7=true, WarbreakerMinimums!E12,100000000000),if($R$8=true, ElantrisMinimums!E12,100000000000),if($R$9=true, WorldhopperMinimums!E12,100000000000)), ,"-",max(if($R$5=true,StormlightMaximums!E12,0),if($R$6=true,MistbornMaximums!E12,0),if($R$7=true, WarbreakerMaximums!E12,0),if($R$8=true, ElantrisMaximums!E12,0),if($R$9=true, WorldhopperMaximums!E12,0)),")") -> 39 (14-48) | G8: =CONCATENATE(round(((if($R$5=true, StormlightAverages!F12,0)+if($R$6=true, MistbornAverages!F12,0)+if($R$7=true, WarbreakerAverages!F12,0)+if($R$8=true, ElantrisAverages!F12,0)+if($R$9=true, WorldhopperAverages!F12,0))/(if(countif($R$5:$R$9,true)=0, 1, COUNTIF($R$5:$R$9,true)))),0)," (",min(if($R$5=true, StormlightMinimums!F12,100000000000),if($R$6=true, MistbornMinimums!F12,100000000000),if($R$7=true, WarbreakerMinimums!F12,100000000000),if($R$8=true, ElantrisMinimums!F12,100000000000),if($R$9=true, WorldhopperMinimums!F12,100000000000)), ,"-",max(if($R$5=true,StormlightMaximums!F12,0),if($R$6=true,MistbornMaximums!F12,0),if($R$7=true, WarbreakerMaximums!F12,0),if($R$8=true, ElantrisMaximums!F12,0),if($R$9=true, WorldhopperMaximums!F12,0)),")") -> 5 (3-8) | H8: =CONCATENATE(round(((if($R$5=true, StormlightAverages!G12,0)+if($R$6=true, MistbornAverages!G12,0)+if($R$7=true, WarbreakerAverages!G12,0)+if($R$8=true, ElantrisAverages!G12,0)+if($R$9=true, WorldhopperAverages!G12,0))/(if(countif($R$5:$R$9,true)=0, 1, COUNTIF($R$5:$R$9,true)))),0)," (",min(if($R$5=true, StormlightMinimums!G12,100000000000),if($R$6=true, MistbornMinimums!G12,100000000000),if($R$7=true, WarbreakerMinimums!G12,100000000000),if($R$8=true, ElantrisMinimums!G12,100000000000),if($R$9=true, WorldhopperMinimums!G12,100000000000)), ,"-",max(if($R$5=true,StormlightMaximums!G12,0),if($R$6=true,MistbornMaximums!G12,0),if($R$7=true, WarbreakerMaximums!G12,0),if($R$8=true, ElantrisMaximums!G12,0),if($R$9=true, WorldhopperMaximums!G12,0)),")") -> 3 (0-8) | I8: =CONCATENATE(round(((if($R$5=true, StormlightAverages!H12,0)+if($R$6=true, MistbornAverages!H12,0)+if($R$7=true, WarbreakerAverages!H12,0)+if($R$8=true, ElantrisAverages!H12,0)+if($R$9=true, WorldhopperAverages!H12,0))/(if(countif($R$5:$R$9,true)=0, 1, COUNTIF($R$5:$R$9,true)))),0)," (",min(if($R$5=true, StormlightMinimums!H12,100000000000),if($R$6=true, MistbornMinimums!H12,100000000000),if($R$7=true, WarbreakerMinimums!H12,100000000000),if($R$8=true, ElantrisMinimums!H12,100000000000),if($R$9=true, WorldhopperMinimums!H12,100000000000)), ,"-",max(if($R$5=true,StormlightMaximums!H12,0),if($R$6=true,MistbornMaximums!H12,0),if($R$7=true, WarbreakerMaximums!H12,0),if($R$8=true, ElantrisMaximums!H12,0),if($R$9=true, WorldhopperMaximums!H12,0)),")") -> 16 (0-28) | J8: =CONCATENATE(round(((if($R$5=true, StormlightAverages!I12,0)+if($R$6=true, MistbornAverages!I12,0)+if($R$7=true, WarbreakerAverages!I12,0)+if($R$8=true, ElantrisAverages!I12,0)+if($R$9=true, WorldhopperAverages!I12,0))/(if(countif($R$5:$R$9,true)=0, 1, COUNTIF($R$5:$R$9,true)))),0)," (",min(if($R$5=true, StormlightMinimums!I12,100000000000),if($R$6=true, MistbornMinimums!I12,100000000000),if($R$7=true, WarbreakerMinimums!I12,100000000000),if($R$8=true, ElantrisMinimums!I12,100000000000),if($R$9=true, WorldhopperMinimums!I12,100000000000)), ,"-",max(if($R$5=true,StormlightMaximums!I12,0),if($R$6=true,MistbornMaximums!I12,0),if($R$7=true, WarbreakerMaximums!I12,0),if($R$8=true, ElantrisMaximums!I12,0),if($R$9=true, WorldhopperMaximums!I12,0)),")") -> 10 (0-21) | ... L8: =CONCATENATE(round(((if($R$5=true, StormlightAverages!K12,0)+if($R$6=true, MistbornAverages!K12,0)+if($R$7=true, WarbreakerAverages!K12,0)+if($R$8=true, ElantrisAverages!K12,0)+if($R$9=true, WorldhopperAverages!K12,0))/(if(countif($R$5:$R$9,true)=0, 1, COUNTIF($R$5:$R$9,true)))),0)," (",min(if($R$5=true, StormlightMinimums!K12,100000000000),if($R$6=true, MistbornMinimums!K12,100000000000),if($R$7=true, WarbreakerMinimums!K12,100000000000),if($R$8=true, ElantrisMinimums!K12,100000000000),if($R$9=true, WorldhopperMinimums!K12,100000000000)), ,"-",max(if($R$5=true,StormlightMaximums!K12,0),if($R$6=true,MistbornMaximums!K12,0),if($R$7=true, WarbreakerMaximums!K12,0),if($R$8=true, ElantrisMaximums!K12,0),if($R$9=true, WorldhopperMaximums!K12,0)),")") -> 9 (6-11) | M8: =CONCATENATE(round(((if($R$5=true, StormlightAverages!M12,0)+if($R$6=true, MistbornAverages!M12,0)+if($R$7=true, WarbreakerAverages!M12,0)+if($R$8=true, ElantrisAverages!M12,0)+if($R$9=true, WorldhopperAverages!M12,0))/(if(countif($R$5:$R$9,true)=0, 1, COUNTIF($R$5:$R$9,true)))),0)," (",min(if($R$5=true, StormlightMinimums!L12,100000000000),if($R$6=true, MistbornMinimums!L12,100000000000),if($R$7=true, WarbreakerMinimums!L12,100000000000),if($R$8=true, ElantrisMinimums!L12,100000000000),if($R$9=true, WorldhopperMinimums!L12,100000000000)), ,"-",max(if($R$5=true,StormlightMaximums!L12,0),if($R$6=true,MistbornMaximums!L12,0),if($R$7=true, WarbreakerMaximums!L12,0),if($R$8=true, ElantrisMaximums!L12,0),if($R$9=true, WorldhopperMaximums!L12,0)),")") -> 7 (5-9) | N8: =CONCATENATE(round(((if($R$5=true, StormlightAverages!N12,0)+if($R$6=true, MistbornAverages!N12,0)+if($R$7=true, WarbreakerAverages!N12,0)+if($R$8=true, ElantrisAverages!N12,0)+if($R$9=true, WorldhopperAverages!N12,0))/(if(countif($R$5:$R$9,true)=0, 1, COUNTIF($R$5:$R$9,true)))),0)," (",min(if($R$5=true, StormlightMinimums!M12,100000000000),if($R$6=true, MistbornMinimums!M12,100000000000),if($R$7=true, WarbreakerMinimums!M12,100000000000),if($R$8=true, ElantrisMinimums!M12,100000000000),if($R$9=true, WorldhopperMinimums!M12,100000000000)), ,"-",max(if($R$5=true,StormlightMaximums!M12,0),if($R$6=true,MistbornMaximums!M12,0),if($R$7=true, WarbreakerMaximums!M12,0),if($R$8=true, ElantrisMaximums!M12,0),if($R$9=true, WorldhopperMaximums!M12,0)),")") -> 18 (7-42) | O8: =CONCATENATE(round(((if($R$5=true, StormlightAverages!O12,0)+if($R$6=true, MistbornAverages!O12,0)+if($R$7=true, WarbreakerAverages!O12,0)+if($R$8=true, ElantrisAverages!O12,0)+if($R$9=true, WorldhopperAverages!O12,0))/(if(countif($R$5:$R$9,true)=0, 1, COUNTIF($R$5:$R$9,true)))),0)," (",min(if($R$5=true, StormlightMinimums!N12,100000000000),if($R$6=true, MistbornMinimums!N12,100000000000),if($R$7=true, WarbreakerMinimums!N12,100000000000),if($R$8=true, ElantrisMinimums!N12,100000000000),if($R$9=true, WorldhopperMinimums!N12,100000000000)), ,"-",max(if($R$5=true,StormlightMaximums!N12,0),if($R$6=true,MistbornMaximums!N12,0),if($R$7=true, WarbreakerMaximums!N12,0),if($R$8=true, ElantrisMaximums!N12,0),if($R$9=true, WorldhopperMaximums!N12,0)),")") -> 24 (7-50) | Q8: Elantris | R8: FALSE
A9: 2 | B9: Boss | C9: =CONCATENATE(round(((if($R$5=true, StormlightAverages!B13,0)+if($R$6=true, MistbornAverages!B13,0)+if($R$7=true, WarbreakerAverages!B13,0)+if($R$8=true, ElantrisAverages!B13,0)+if($R$9=true, WorldhopperAverages!B13,0))/(if(countif($R$5:$R$9,true)=0, 1, COUNTIF($R$5:$R$9,true)))),0)," (",min(if($R$5=true, StormlightMinimums!B13,100000000000),if($R$6=true, MistbornMinimums!B13,100000000000),if($R$7=true, WarbreakerMinimums!B13,100000000000),if($R$8=true, ElantrisMinimums!B13,100000000000),if($R$9=true, WorldhopperMinimums!B13,100000000000)), ,"-",max(if($R$5=true,StormlightMaximums!B13,0),if($R$6=true,MistbornMaximums!B13,0),if($R$7=true, WarbreakerMaximums!B13,0),if($R$8=true, ElantrisMaximums!B13,0),if($R$9=true, WorldhopperMaximums!B13,0)),")") -> 19 (18-19) | D9: =CONCATENATE(round(((if($R$5=true, StormlightAverages!C13,0)+if($R$6=true, MistbornAverages!C13,0)+if($R$7=true, WarbreakerAverages!C13,0)+if($R$8=true, ElantrisAverages!C13,0)+if($R$9=true, WorldhopperAverages!C13,0))/(if(countif($R$5:$R$9,true)=0, 1, COUNTIF($R$5:$R$9,true)))),0)," (",min(if($R$5=true, StormlightMinimums!C13,100000000000),if($R$6=true, MistbornMinimums!C13,100000000000),if($R$7=true, WarbreakerMinimums!C13,100000000000),if($R$8=true, ElantrisMinimums!C13,100000000000),if($R$9=true, WorldhopperMinimums!C13,100000000000)), ,"-",max(if($R$5=true,StormlightMaximums!C13,0),if($R$6=true,MistbornMaximums!C13,0),if($R$7=true, WarbreakerMaximums!C13,0),if($R$8=true, ElantrisMaximums!C13,0),if($R$9=true, WorldhopperMaximums!C13,0)),")") -> 15 (14-15) | E9: =CONCATENATE(round(((if($R$5=true, StormlightAverages!D13,0)+if($R$6=true, MistbornAverages!D13,0)+if($R$7=true, WarbreakerAverages!D13,0)+if($R$8=true, ElantrisAverages!D13,0)+if($R$9=true, WorldhopperAverages!D13,0))/(if(countif($R$5:$R$9,true)=0, 1, COUNTIF($R$5:$R$9,true)))),0)," (",min(if($R$5=true, StormlightMinimums!D13,100000000000),if($R$6=true, MistbornMinimums!D13,100000000000),if($R$7=true, WarbreakerMinimums!D13,100000000000),if($R$8=true, ElantrisMinimums!D13,100000000000),if($R$9=true, WorldhopperMinimums!D13,100000000000)), ,"-",max(if($R$5=true,StormlightMaximums!D13,0),if($R$6=true,MistbornMaximums!D13,0),if($R$7=true, WarbreakerMaximums!D13,0),if($R$8=true, ElantrisMaximums!D13,0),if($R$9=true, WorldhopperMaximums!D13,0)),")") -> 16 (16-16) | F9: =CONCATENATE(round(((if($R$5=true, StormlightAverages!E13,0)+if($R$6=true, MistbornAverages!E13,0)+if($R$7=true, WarbreakerAverages!E13,0)+if($R$8=true, ElantrisAverages!E13,0)+if($R$9=true, WorldhopperAverages!E13,0))/(if(countif($R$5:$R$9,true)=0, 1, COUNTIF($R$5:$R$9,true)))),0)," (",min(if($R$5=true, StormlightMinimums!E13,100000000000),if($R$6=true, MistbornMinimums!E13,100000000000),if($R$7=true, WarbreakerMinimums!E13,100000000000),if($R$8=true, ElantrisMinimums!E13,100000000000),if($R$9=true, WorldhopperMinimums!E13,100000000000)), ,"-",max(if($R$5=true,StormlightMaximums!E13,0),if($R$6=true,MistbornMaximums!E13,0),if($R$7=true, WarbreakerMaximums!E13,0),if($R$8=true, ElantrisMaximums!E13,0),if($R$9=true, WorldhopperMaximums!E13,0)),")") -> 135 (126-144) | G9: =CONCATENATE(round(((if($R$5=true, StormlightAverages!F13,0)+if($R$6=true, MistbornAverages!F13,0)+if($R$7=true, WarbreakerAverages!F13,0)+if($R$8=true, ElantrisAverages!F13,0)+if($R$9=true, WorldhopperAverages!F13,0))/(if(countif($R$5:$R$9,true)=0, 1, COUNTIF($R$5:$R$9,true)))),0)," (",min(if($R$5=true, StormlightMinimums!F13,100000000000),if($R$6=true, MistbornMinimums!F13,100000000000),if($R$7=true, WarbreakerMinimums!F13,100000000000),if($R$8=true, ElantrisMinimums!F13,100000000000),if($R$9=true, WorldhopperMinimums!F13,100000000000)), ,"-",max(if($R$5=true,StormlightMaximums!F13,0),if($R$6=true,MistbornMaximums!F13,0),if($R$7=true, WarbreakerMaximums!F13,0),if($R$8=true, ElantrisMaximums!F13,0),if($R$9=true, WorldhopperMaximums!F13,0)),")") -> 5 (5-5) | H9: =CONCATENATE(round(((if($R$5=true, StormlightAverages!G13,0)+if($R$6=true, MistbornAverages!G13,0)+if($R$7=true, WarbreakerAverages!G13,0)+if($R$8=true, ElantrisAverages!G13,0)+if($R$9=true, WorldhopperAverages!G13,0))/(if(countif($R$5:$R$9,true)=0, 1, COUNTIF($R$5:$R$9,true)))),0)," (",min(if($R$5=true, StormlightMinimums!G13,100000000000),if($R$6=true, MistbornMinimums!G13,100000000000),if($R$7=true, WarbreakerMinimums!G13,100000000000),if($R$8=true, ElantrisMinimums!G13,100000000000),if($R$9=true, WorldhopperMinimums!G13,100000000000)), ,"-",max(if($R$5=true,StormlightMaximums!G13,0),if($R$6=true,MistbornMaximums!G13,0),if($R$7=true, WarbreakerMaximums!G13,0),if($R$8=true, ElantrisMaximums!G13,0),if($R$9=true, WorldhopperMaximums!G13,0)),")") -> 0 (0-0) | I9: =CONCATENATE(round(((if($R$5=true, StormlightAverages!H13,0)+if($R$6=true, MistbornAverages!H13,0)+if($R$7=true, WarbreakerAverages!H13,0)+if($R$8=true, ElantrisAverages!H13,0)+if($R$9=true, WorldhopperAverages!H13,0))/(if(countif($R$5:$R$9,true)=0, 1, COUNTIF($R$5:$R$9,true)))),0)," (",min(if($R$5=true, StormlightMinimums!H13,100000000000),if($R$6=true, MistbornMinimums!H13,100000000000),if($R$7=true, WarbreakerMinimums!H13,100000000000),if($R$8=true, ElantrisMinimums!H13,100000000000),if($R$9=true, WorldhopperMinimums!H13,100000000000)), ,"-",max(if($R$5=true,StormlightMaximums!H13,0),if($R$6=true,MistbornMaximums!H13,0),if($R$7=true, WarbreakerMaximums!H13,0),if($R$8=true, ElantrisMaximums!H13,0),if($R$9=true, WorldhopperMaximums!H13,0)),")") -> 11 (8-14) | J9: =CONCATENATE(round(((if($R$5=true, StormlightAverages!I13,0)+if($R$6=true, MistbornAverages!I13,0)+if($R$7=true, WarbreakerAverages!I13,0)+if($R$8=true, ElantrisAverages!I13,0)+if($R$9=true, WorldhopperAverages!I13,0))/(if(countif($R$5:$R$9,true)=0, 1, COUNTIF($R$5:$R$9,true)))),0)," (",min(if($R$5=true, StormlightMinimums!I13,100000000000),if($R$6=true, MistbornMinimums!I13,100000000000),if($R$7=true, WarbreakerMinimums!I13,100000000000),if($R$8=true, ElantrisMinimums!I13,100000000000),if($R$9=true, WorldhopperMinimums!I13,100000000000)), ,"-",max(if($R$5=true,StormlightMaximums!I13,0),if($R$6=true,MistbornMaximums!I13,0),if($R$7=true, WarbreakerMaximums!I13,0),if($R$8=true, ElantrisMaximums!I13,0),if($R$9=true, WorldhopperMaximums!I13,0)),")") -> 6 (5-6) | ... L9: =CONCATENATE(round(((if($R$5=true, StormlightAverages!K13,0)+if($R$6=true, MistbornAverages!K13,0)+if($R$7=true, WarbreakerAverages!K13,0)+if($R$8=true, ElantrisAverages!K13,0)+if($R$9=true, WorldhopperAverages!K13,0))/(if(countif($R$5:$R$9,true)=0, 1, COUNTIF($R$5:$R$9,true)))),0)," (",min(if($R$5=true, StormlightMinimums!K13,100000000000),if($R$6=true, MistbornMinimums!K13,100000000000),if($R$7=true, WarbreakerMinimums!K13,100000000000),if($R$8=true, ElantrisMinimums!K13,100000000000),if($R$9=true, WorldhopperMinimums!K13,100000000000)), ,"-",max(if($R$5=true,StormlightMaximums!K13,0),if($R$6=true,MistbornMaximums!K13,0),if($R$7=true, WarbreakerMaximums!K13,0),if($R$8=true, ElantrisMaximums!K13,0),if($R$9=true, WorldhopperMaximums!K13,0)),")") -> 0 (0-0) | M9: =CONCATENATE(round(((if($R$5=true, StormlightAverages!M13,0)+if($R$6=true, MistbornAverages!M13,0)+if($R$7=true, WarbreakerAverages!M13,0)+if($R$8=true, ElantrisAverages!M13,0)+if($R$9=true, WorldhopperAverages!M13,0))/(if(countif($R$5:$R$9,true)=0, 1, COUNTIF($R$5:$R$9,true)))),0)," (",min(if($R$5=true, StormlightMinimums!L13,100000000000),if($R$6=true, MistbornMinimums!L13,100000000000),if($R$7=true, WarbreakerMinimums!L13,100000000000),if($R$8=true, ElantrisMinimums!L13,100000000000),if($R$9=true, WorldhopperMinimums!L13,100000000000)), ,"-",max(if($R$5=true,StormlightMaximums!L13,0),if($R$6=true,MistbornMaximums!L13,0),if($R$7=true, WarbreakerMaximums!L13,0),if($R$8=true, ElantrisMaximums!L13,0),if($R$9=true, WorldhopperMaximums!L13,0)),")") -> 8 (8-8) | N9: =CONCATENATE(round(((if($R$5=true, StormlightAverages!N13,0)+if($R$6=true, MistbornAverages!N13,0)+if($R$7=true, WarbreakerAverages!N13,0)+if($R$8=true, ElantrisAverages!N13,0)+if($R$9=true, WorldhopperAverages!N13,0))/(if(countif($R$5:$R$9,true)=0, 1, COUNTIF($R$5:$R$9,true)))),0)," (",min(if($R$5=true, StormlightMinimums!M13,100000000000),if($R$6=true, MistbornMinimums!M13,100000000000),if($R$7=true, WarbreakerMinimums!M13,100000000000),if($R$8=true, ElantrisMinimums!M13,100000000000),if($R$9=true, WorldhopperMinimums!M13,100000000000)), ,"-",max(if($R$5=true,StormlightMaximums!M13,0),if($R$6=true,MistbornMaximums!M13,0),if($R$7=true, WarbreakerMaximums!M13,0),if($R$8=true, ElantrisMaximums!M13,0),if($R$9=true, WorldhopperMaximums!M13,0)),")") -> 15 (12-17) | O9: =CONCATENATE(round(((if($R$5=true, StormlightAverages!O13,0)+if($R$6=true, MistbornAverages!O13,0)+if($R$7=true, WarbreakerAverages!O13,0)+if($R$8=true, ElantrisAverages!O13,0)+if($R$9=true, WorldhopperAverages!O13,0))/(if(countif($R$5:$R$9,true)=0, 1, COUNTIF($R$5:$R$9,true)))),0)," (",min(if($R$5=true, StormlightMinimums!N13,100000000000),if($R$6=true, MistbornMinimums!N13,100000000000),if($R$7=true, WarbreakerMinimums!N13,100000000000),if($R$8=true, ElantrisMinimums!N13,100000000000),if($R$9=true, WorldhopperMinimums!N13,100000000000)), ,"-",max(if($R$5=true,StormlightMaximums!N13,0),if($R$6=true,MistbornMaximums!N13,0),if($R$7=true, WarbreakerMaximums!N13,0),if($R$8=true, ElantrisMaximums!N13,0),if($R$9=true, WorldhopperMaximums!N13,0)),")") -> 26 (20-32) | Q9: Worldhopper | R9: FALSE
